Workbook

Sheet Global(excl COCLMX)
A1: 1 | C1: Region:Global
H2: Updated Date | J2: =ID!J2 -> 46000 | L2: =SUMPRODUCT(J4:T4,J12:T12)/10^8 -> 1089.8199
C3: S&R&A Monthly Metrics | F3: =J3 -> 45962 | G3: =K3 -> 45931 | H3: MoM % | J3: 45962 | K3: 45931 | L3: 45901 | M3: 45870 | N3: 45839 | O3: 45809 | P3: 45778 | Q3: 45748 | R3: 45717 | S3: 45689 | T3: 45658 | U3: 45627 | V3: 45597 | W3: 45566 | X3: 45536 | Y3: 45505 | Z3: 45474 | AA3: 45444 | AB3: 45413 | AC3: 45383 | AD3: 45352 | AE3: 45323 | AF3: 45292 | AG3: 45261 | AH3: 45231 | AI3: 45200 | AJ3: 45170 | AK3: 45139 | AL3: 45108 | AM3: 45078 | AN3: 45047 | AO3: 45017 | AP3: 44986 | AQ3: 44958 | AR3: 44927 | AS3: 44896 | AT3: 44866 | AU3: 44835 | AV3: 44805 | AW3: 44774 | AX3: 44743 | AY3: 44713 | AZ3: 44682 | BA3: 44652 | BB3: 44621 | BC3: 44593 | BD3: 44562
J4: =day(EOMONTH(J3,0)) -> 30 | K4: =day(EOMONTH(K3,0)) -> 31 | L4: =day(EOMONTH(L3,0)) -> 30 | M4: =day(EOMONTH(M3,0)) -> 31 | N4: =day(EOMONTH(N3,0)) -> 31 | O4: =day(EOMONTH(O3,0)) -> 30 | P4: =day(EOMONTH(P3,0)) -> 31 | Q4: =day(EOMONTH(Q3,0)) -> 30 | ... T4: =day(EOMONTH(T3,0)) -> 31
D5: UNIT
B6: Platform DAU | C6: Platform DAU | D6: # | F6: =J6 -> 1.5075388e+08 | G6: =K6 -> 1.4702327e+08 | H6: =IFERROR(F6/G6-1,"-") -> 0.025374256 | J6: 1.5075388e+08 | K6: 1.4702327e+08 | L6: 1.4339402e+08 | M6: 1.4134278e+08 | N6: 1.3979223e+08 | O6: 1.3764766e+08 | P6: 1.356248e+08 | Q6: 1.3263935e+08 | R6: 1.3635458e+08 | S6: 1.3320974e+08 | T6: 1.3115546e+08 | U6: 1.3430784e+08 | V6: 1.3155056e+08 | W6: 1.2761181e+08 | X6: 1.2560495e+08 | Y6: 1.2426158e+08 | Z6: 1.2284617e+08 | AA6: 1.1923126e+08 | AB6: 1.1733315e+08 | AC6: 116050325 | AD6: 1.1876644e+08 | AE6: 1.1222874e+08 | AF6: 1.1416651e+08 | AG6: 1.1261293e+08 | AH6: 1.12425e+08 | AI6: 106264477 | AJ6: 1.0110142e+08 | AK6: 97604028 | AL6: 92553756 | AM6: 87099000 | AN6: 87858830 | AO6: 87581349 | AP6: 87683931 | AQ6: 85097285 | AR6: 84234276 | AS6: 87017245 | AT6: 88345852 | AU6: 85789233 | AV6: 86732608 | AW6: 84927886 | AX6: 83031018 | AY6: 81653203 | AZ6: 80257489 | BA6: 82366574 | BB6: 80829064 | BC6: 78184659 | BD6: 76167898
B8: Avg No. of Modules in HP Layout | C8: Buyer | D8: # | F8: =J8 -> 22848272 | G8: =K8 -> 21330354 | H8: =IFERROR(F8/G8-1,"-") -> 0.071162316 | J8: 22848272 | K8: 21330354 | L8: 20592090 | M8: 20143537 | N8: 20321959 | O8: 19867291 | P8: 19155328 | Q8: 18081946 | R8: 19616770 | S8: 18272896 | T8: 17463776 | U8: 18282416 | V8: 17827775 | W8: 16854567 | X8: 16651151 | Y8: 16248783 | Z8: 16067678 | AA8: 15432068 | AB8: 15063566 | AC8: 14605379 | AD8: 16829181 | AE8: 14327271 | AF8: 14887087 | AG8: 14908772 | AH8: 14984239 | AI8: 14420602 | AJ8: 13768077 | AK8: 13463720 | AL8: 12382372 | AM8: 10818861 | AN8: 10326826 | AO8: 10450498 | AP8: 10355062 | AQ8: 9635834.2 | AR8: 9383052.4 | AS8: 9897352.3 | AT8: 9835640.4 | AU8: 9518816.7 | AV8: 10160133 | AW8: 10501366 | AX8: 10498719 | AY8: 4039152.2 | AZ8: 3735740.2 | BA8: 4730740.3 | BB8: 3739082.5 | BC8: 3417895.6 | BD8: 3195191.8
B9: Avg No. of Modules in HP Layout | C9: Buyer% | D9: % | F9: =J9 -> 0.15156009 | G9: =K9 -> 0.14508148 | H9: =IFERROR(F9/G9-1,"-") -> 0.044654973 | J9: 0.15156009 | K9: 0.14508148 | L9: 0.14360495 | M9: 0.1425155 | N9: 0.14537259 | O9: 0.14433439 | P9: 0.14123765 | Q9: 0.13632415 | R9: 0.14386586 | S9: 0.13717388 | T9: 0.13315325 | U9: 0.13612323 | V9: 0.13552033 | W9: 0.13207686 | X9: 0.13256763 | Y9: 0.13076272 | Z9: 0.1307951 | AA9: 0.12942972 | AB9: 0.12838286 | AC9: 0.12585384 | AD9: 0.14169981 | AE9: 0.12766134 | AF9: 0.13039802 | AG9: 0.13238952 | AH9: 0.13328209 | AI9: 0.13570482 | AJ9: 0.13618084 | AK9: 0.13794226 | AL9: 0.13378574 | AM9: 0.12421338 | AN9: 0.11753885 | AO9: 0.11932333 | AP9: 0.11809532 | AQ9: 0.11323316 | AR9: 0.11139233 | AS9: 0.11374013 | AT9: 0.11133109 | AU9: 0.11095584 | AV9: 0.11714317 | AW9: 0.12365039 | AX9: 0.12644334 | AY9: 0.049467161 | AZ9: 0.046546936 | BA9: 0.057435196 | BB9: 0.046259134 | BC9: 0.043715681 | BD9: 0.041949323
B10: Avg No. of Modules in HP Layout | C10: Order | D10: # | F10: =J10 -> 40183473 | G10: =K10 -> 36825405 | H10: =IFERROR(F10/G10-1,"-") -> 0.091188898 | J10: 40183473 | K10: 36825405 | L10: 35344382 | M10: 34385453 | N10: 34637474 | O10: 34115472 | P10: 32196015 | Q10: 30037210 | R10: 33465607 | S10: 30269953 | T10: 28913942 | U10: 30823142 | V10: 29915552 | W10: 27687849 | X10: 27419860 | Y10: 26576347 | Z10: 26403680 | AA10: 25399176 | AB10: 24664328 | AC10: 23743584 | AD10: 28166924 | AE10: 23206770 | AF10: 24242432 | AG10: 24671680 | AH10: 24986840 | AI10: 23734881 | AJ10: 22366999 | AK10: 21768550 | AL10: 20286892 | AM10: 17704705 | AN10: 16428382 | AO10: 17073801 | AP10: 16672848 | AQ10: 15210721 | AR10: 14776304 | AS10: 16026655 | AT10: 15894468 | AU10: 15144487 | AV10: 16461134 | AW10: 17349756 | AX10: 17720254 | AY10: 6851324.1 | AZ10: 6154880.5 | BA10: 8594126.4 | BB10: 6538882.5 | BC10: 5785703.7 | BD10: 5313141.8
C11: Order/U | D11: # | F11: =J11 -> 0.26655017 | G11: =K11 -> 0.2504733 | H11: =IFERROR(F11/G11-1,"-") -> 0.06418597 | J11: 0.26655017 | K11: 0.2504733 | L11: 0.24648436 | M11: 0.24327705 | N11: 0.24777824 | O11: 0.24784637 | P11: 0.23739032 | Q11: 0.22645777 | R11: 0.24543075 | S11: 0.22723529 | T11: 0.2204555 | U11: 0.22949622 | V11: 0.22740725 | W11: 0.21696933 | X11: 0.21830238 | Y11: 0.21387421 | Z11: 0.21493286 | AA11: 0.21302447 | AB11: 0.21020767 | AC11: 0.2045973 | AD11: 0.23716233 | AE11: 0.20678099 | AF11: 0.21234276 | AG11: 0.2190839 | AH11: 0.22225341 | AI11: 0.22335668 | AJ11: 0.22123328 | AK11: 0.22302922 | AL11: 0.21919037 | AM11: 0.20327105 | AN11: 0.18698612 | AO11: 0.19494791 | AP11: 0.19014713 | AQ11: 0.17874508 | AR11: 0.17541914 | AS11: 0.18417792 | AT11: 0.17991187 | AU11: 0.17653132 | AV11: 0.18979175 | AW11: 0.20428809 | AX11: 0.21341728 | AY11: 0.083907597 | AZ11: 0.076689173 | BA11: 0.10433998 | BB11: 0.080897664 | BC11: 0.074000498 | BD11: 0.069755657
B12: HP UV | C12: GMV | D12: # | F12: =J12 -> 3.9634858e+08 | G12: =K12 -> 3.5532994e+08 | H12: =IFERROR(F12/G12-1,"-") -> 0.1154382 | J12: 3.9634858e+08 | K12: 3.5532994e+08 | L12: 3.4321822e+08 | M12: 3.2765642e+08 | N12: 3.2628687e+08 | O12: 3.2649974e+08 | P12: 3.1419371e+08 | Q12: 2.9282887e+08 | R12: 3.1668665e+08 | S12: 3.0356658e+08 | T12: 2.8614516e+08 | U12: 2.9922677e+08 | V12: 3.003348e+08 | W12: 2.8229191e+08 | X12: 2.7204971e+08 | Y12: 2.5158851e+08 | Z12: 2.489532e+08 | AA12: 2.4486364e+08 | AB12: 2.4283384e+08 | AC12: 2.3495554e+08 | AD12: 2.6078334e+08 | AE12: 2.2824681e+08 | AF12: 2.4481249e+08 | AG12: 2.4597506e+08 | AH12: 2.4495409e+08 | AI12: 2.2232663e+08 | AJ12: 2.1219819e+08 | AK12: 2.0564457e+08 | AL12: 1.9688585e+08 | AM12: 1.8646799e+08 | AN12: 1.8315308e+08 | AO12: 1.8507196e+08 | AP12: 1.8530474e+08 | AQ12: 1.8154518e+08 | AR12: 1.7146202e+08 | AS12: 1.843303e+08 | AT12: 1.8704811e+08 | AU12: 1.7366133e+08 | AV12: 1.9024642e+08 | AW12: 1.8982306e+08 | AX12: 1.8951358e+08 | AY12: 56752694 | AZ12: 50166169 | BA12: 69907530 | BB12: 54267508 | BC12: 49459567 | BD12: 48553139
J13: =J12/K12 -> 1.1154382 | K13: =K12/L12 -> 1.0352887 | V13: =V12/W12 -> 1.0639157 | W13: =W12/X12 -> 1.0376483
B14: Avg No. of Modules in HP Layout | C14: Ads Gross Rev | D14: # | F14: =J14 -> 14118402 | G14: =K14 -> 12353602 | H14: =IFERROR(F14/G14-1,"-") -> 0.1428571 | J14: 14118402 | K14: 12353602 | L14: 11651783 | M14: 10844701 | N14: 10598892 | O14: 10145355 | P14: 9005882.2 | Q14: 7950545 | R14: 8352182.6 | S14: 7724586.2 | T14: 7291682.1 | U14: 8171731.1 | V14: 7810394.6 | W14: 7303318.8 | X14: 6945214.3 | Y14: 6426808.1 | Z14: 6238831.3 | AA14: 5962930.8 | AB14: 5514242.6 | AC14: 5130076 | AD14: 5403784.8 | AE14: 4504739 | AF14: 4952246.2 | AG14: 5090619 | AH14: 4955906.2 | AI14: 4483549.7 | AJ14: 4339364.8 | AK14: 4208811.6 | AL14: 4061940 | AM14: 3852406.4 | AN14: 3640747.9 | AO14: 3662444.9 | AP14: 3699929.5 | AQ14: 3629195 | AR14: 3348763.4
B15: Avg No. of Modules in HP Layout | C15: Gross Take Rate | D15: % | F15: =J15 -> 0.035621173 | G15: =K15 -> 0.034766566 | H15: =IFERROR(F15/G15-1,"-") -> 0.024581286 | J15: 0.035621173 | K15: 0.034766566 | L15: 0.033948615 | M15: 0.033097783 | N15: 0.032483355 | O15: 0.031073088 | P15: 0.02866347 | Q15: 0.027150824 | R15: 0.026373649 | S15: 0.025446102 | T15: 0.025482458 | U15: 0.027309493 | V15: 0.026005626 | W15: 0.025871513 | X15: 0.02552921 | Y15: 0.025544919 | Z15: 0.025060258 | AA15: 0.024352047 | AB15: 0.022707884 | AC15: 0.021834242 | AD15: 0.020721357 | AE15: 0.019736263 | AF15: 0.020228732 | AG15: 0.020695672 | AH15: 0.02023198 | AI15: 0.020166499 | AJ15: 0.020449584 | AK15: 0.020466437 | AL15: 0.020630939 | AM15: 0.02065988 | AN15: 0.01987817 | AO15: 0.019789301 | AP15: 0.019966729 | AQ15: 0.019990588 | AR15: 0.019530643
B16: HP UV | C16: Ads Direct ROI | D16: # | F16: =J16 -> 8.2181463 | G16: =K16 -> 8.1309657 | H16: =IFERROR(F16/G16-1,"-") -> 0.010722051 | J16: 8.2181463 | K16: 8.1309657 | L16: 7.945723 | M16: 7.7278759 | N16: 7.6701692 | O16: 8.0766213 | P16: 7.969075 | Q16: 8.0443702 | R16: 8.0976582 | S16: 8.0489877 | T16: 8.2040596 | U16: 7.5139452 | V16: 8.0845926 | W16: 7.6248678 | X16: 7.8183603 | Y16: 6.9366999 | Z16: 6.8869691 | AA16: 6.5641687 | AB16: 6.8616282 | AC16: 6.615458 | AD16: 6.5464385 | AE16: 6.2902636 | AF16: 6.2891044 | AG16: 6.1886902 | AH16: 6.1876383 | AI16: 6.0202588 | AJ16: 6.1515051 | AK16: 6.085474 | AL16: 5.9671388 | AM16: 5.9019645 | AN16: 5.9085521 | AO16: 5.8539045 | AP16: 5.7198079 | AQ16: 5.6951383 | AR16: 5.6830048
B18: Avg No. of Modules in HP Layout | C18: Ads Net Rev | D18: # | F18: =J18 -> 13309600 | G18: =K18 -> 11698097 | H18: =IFERROR(F18/G18-1,"-") -> 0.13775774 | J18: 13309600 | K18: 11698097 | L18: 11045886 | M18: 10381846 | N18: 10190472 | O18: 9709661.6 | P18: 8592518.4 | Q18: 7635413.7 | R18: 8019541.8 | S18: 7441328.2 | T18: 7022526 | U18: 7796512.3 | V18: 7411223.3 | W18: 6954565.1 | X18: 6611096.3 | Y18: 6148337.7 | Z18: 5995099.8 | AA18: 5737838.1 | AB18: 5310930.1 | AC18: 4908906.7
C19: Net Take Rate | D19: % | F19: =J19 -> 0.033580542 | G19: =K19 -> 0.032921788 | H19: =IFERROR(F19/G19-1,"-") -> 0.020009664 | J19: 0.033580542 | K19: 0.032921788 | L19: 0.032183275 | M19: 0.031685159 | N19: 0.031231635 | O19: 0.02973865 | P19: 0.027347837 | Q19: 0.026074662 | R19: 0.025323271 | S19: 0.024513002 | T19: 0.024541831 | U19: 0.026055531 | V19: 0.024676539 | W19: 0.024636077 | X19: 0.02430106 | Y19: 0.02443807 | Z19: 0.024081232 | AA19: 0.023432789 | AB19: 0.021870634 | AC19: 0.020892918
B21: Avg No. of Modules in HP Layout | C21: Ads Net Rev (excl 1p/sip) | D21: # | F21: =J21 -> 13146811 | G21: =K21 -> 11535172 | H21: =IFERROR(F21/G21-1,"-") -> 0.1397152 | J21: 13146811 | K21: 11535172 | L21: 10906468 | M21: 10248486 | N21: 10065428 | O21: 9570544.7 | P21: 8494231.3 | Q21: 7575477.5 | R21: 7917604.6 | S21: 7289437.4 | T21: 6866180.5 | U21: 7638555.5 | V21: 7262759.8 | W21: 6617254.7 | X21: 6151034.1 | Y21: 5563229.5 | Z21: 5350201.2 | AA21: 5207659.5 | AB21: 4869499.1 | AC21: 4633820.9
C22: Net Take Rate (excl 1p/sip) | D22: % | F22: =J22 -> 0.033169819 | G22: =K22 -> 0.03246327 | H22: =IFERROR(F22/G22-1,"-") -> 0.021764543 | J22: 0.033169819 | K22: 0.03246327 | L22: 0.031777065 | M22: 0.031278148 | N22: 0.030848402 | O22: 0.029312564 | P22: 0.027035013 | Q22: 0.025869982 | R22: 0.025001384 | S22: 0.024012648 | T22: 0.023995445 | U22: 0.025527648 | V22: 0.024182212 | W22: 0.023441177 | X22: 0.022609964 | Y22: 0.022112415 | Z22: 0.021490791 | AA22: 0.02126759 | AB22: 0.020052803 | AC22: 0.019722118
B24: Avg No. of Modules in HP Layout | C24: Commission Fee | D24: USD | F24: =J24 -> 38623530 | G24: =K24 -> 34197963 | H24: =IFERROR(F24/G24-1,"-") -> 0.12941023 | J24: 38623530 | K24: 34197963 | L24: 32240795 | M24: 30312115 | N24: 29994070 | O24: 29836985 | P24: 27524134 | Q24: 25206744 | R24: 25912669 | S24: 23620745 | T24: 21885824 | U24: 20866535 | V24: 21238736 | W24: 19670100 | X24: 18955673 | Y24: 16533495 | Z24: 15947206 | AA24: 14898795 | AB24: 14615455 | AC24: 13986237 | AD24: 14676991 | AE24: 12474366 | AF24: 13073946 | AG24: 13568870 | AH24: 13159072 | AI24: 11506255 | AJ24: 11050316 | AK24: 10820175 | AL24: 10382889 | AM24: 9610230.3 | AN24: 9136076.5 | AO24: 8774412.4 | AP24: 8457487.7 | AQ24: 8146767.6 | AR24: 7768942.8 | AS24: 7134477.8 | AT24: 7899756.1 | AU24: 6892895.1 | AV24: 7567013.3 | AW24: 6981648 | AX24: 6666181.4 | AY24: 6905789.1 | AZ24: 6510684.8 | BA24: 6428439.3 | BB24: 5630806.3 | BC24: 4972165.9 | BD24: 4392557.7
B25: Avg No. of Modules in HP Layout | C25: Commission Rate | D25: % | F25: =J25 -> 0.097448386 | G25: =K25 -> 0.096242844 | H25: =IFERROR(F25/G25-1,"-") -> 0.012526049 | J25: 0.097448386 | K25: 0.096242844 | L25: 0.093936723 | M25: 0.092511891 | N25: 0.091925458 | O25: 0.091384405 | P25: 0.087602434 | Q25: 0.08608012 | R25: 0.081824319 | S25: 0.077810755 | T25: 0.076485042 | U25: 0.069734855 | V25: 0.070716866 | W25: 0.069679999 | X25: 0.069677239 | Y25: 0.065716413 | Z25: 0.064057043 | AA25: 0.060845273 | AB25: 0.060187061 | AC25: 0.059527167 | AD25: 0.056280403 | AE25: 0.05465297 | AF25: 0.053403917 | AG25: 0.055163601 | AH25: 0.053720565 | AI25: 0.051753832 | AJ25: 0.052075448 | AK25: 0.052615906 | AL25: 0.052735576 | AM25: 0.051538231 | AN25: 0.04988219 | AO25: 0.047410814 | AP25: 0.045640969 | AQ25: 0.044874601 | AR25: 0.045309993 | AS25: 0.038704857 | AT25: 0.04223382 | AU25: 0.039691594 | AV25: 0.0397748 | AW25: 0.036779767 | AX25: 0.035175218 | AY25: 0.12168214 | AZ25: 0.12978238 | BA25: 0.091956321 | BB25: 0.10376018 | BC25: 0.10052991 | BD25: 0.090469079
B26: Avg No. of Modules in HP Layout | C26: Total Rebate | D26: USD | F26: =J26 -> 79639423 | G26: =K26 -> 70171227 | H26: =IFERROR(F26/G26-1,"-") -> 0.13492989 | J26: 79639423 | K26: 70171227 | L26: 65774235 | M26: 61570332 | N26: 61166660 | O26: 62558279 | P26: 53616053 | Q26: 46348825 | R26: 54238371 | S26: 45393364 | T26: 42722186 | U26: 48678483 | V26: 46197666 | W26: 42150851 | X26: 41734107 | Y26: 36631317 | Z26: 34436482 | AA26: 33280846 | AB26: 30934075 | AC26: 30115926 | AD26: 38091460 | AE26: 28764217 | AF26: 29535936 | AG26: 30596451 | AH26: 32014315 | AI26: 31369439 | AJ26: 29758991 | AK26: 28560502 | AL26: 25647879 | AM26: 19199777 | AN26: 15328618 | AO26: 15181193 | AP26: 15127719 | AQ26: 12002625 | AR26: 10417608 | AS26: 11504730 | AT26: 11812327 | AU26: 11252465 | AV26: 14534830 | AW26: 15864418 | AX26: 16943049 | AY26: 16887592 | AZ26: 14875809 | BA26: 18357624 | BB26: 16584802 | BC26: 13621660 | BD26: 12897283
C28: Order% by Channel (incl. ads & non-item cards) | D28: UNIT
C29: Total | F29: =J29 -> 1 | G29: =K29 -> 1 | H29: =IFERROR(F29/G29-1,"-") -> 0 | J29: 1 | K29: 1 | L29: 1 | M29: 1 | N29: 1 | O29: 1 | P29: 1 | Q29: 1 | R29: 1 | S29: 1 | T29: 1 | U29: 1 | V29: 1 | W29: 1 | X29: 1 | Y29: 1 | Z29: 1 | AA29: 1 | AB29: 1 | AC29: 1 | AD29: 1 | AE29: 1 | AF29: 1 | AG29: 1 | AH29: 1 | AI29: 1 | AJ29: 1 | AK29: 1 | AL29: 1 | AM29: 1 | AN29: 1 | AO29: 1 | AP29: 1 | AQ29: 1 | AR29: 1
B30: Platform DAU | C30: Global Search | D30: % | F30: =J30 -> 0.40039399 | G30: =K30 -> 0.40186104 | H30: =IFERROR(F30/G30-1,"-") -> -0.0036506549 | J30: 0.40039399 | K30: 0.40186104 | L30: 0.39993813 | M30: 0.40411987 | N30: 0.40525341 | O30: 0.39716249 | P30: 0.40355987 | Q30: 0.40790435 | R30: 0.39747165 | S30: 0.3973082 | T30: 0.39588731 | U30: 0.39027439 | V30: 0.38663356 | W30: 0.38208039 | X30: 0.38012596 | Y30: 0.37699121 | Z30: 0.37879158 | AA30: 0.37440792 | AB30: 0.37141491 | AC30: 0.37700701 | AD30: 0.35927648 | AE30: 0.35847092 | AF30: 0.35293306 | AG30: 0.33962324 | AH30: 0.3329479 | AI30: 0.33947635 | AJ30: 0.34331107 | AK30: 0.33731394 | AL30: 0.34618488 | AM30: 0.36034173 | AN30: 0.36023254 | AO30: 0.35281023 | AP30: 0.34816529 | AQ30: 0.34873056 | AR30: 0.33895621
B31: Platform DAU | C31: Daily Discover | D31: % | F31: =J31 -> 0.098401385 | G31: =K31 -> 0.096188491 | H31: =IFERROR(F31/G31-1,"-") -> 0.02300581 | J31: 0.098401385 | K31: 0.096188491 | L31: 0.094203303 | M31: 0.09400793 | N31: 0.091610477 | O31: 0.083872498 | P31: 0.081264314 | Q31: 0.077381823 | R31: 0.078406154 | S31: 0.069707936 | T31: 0.068461915 | U31: 0.066846523 | V31: 0.065341511 | W31: 0.064753812 | X31: 0.063687981 | Y31: 0.059815338 | Z31: 0.060165856 | AA31: 0.058757062 | AB31: 0.059647696 | AC31: 0.05870264 | AD31: 0.057540004 | AE31: 0.053957685 | AF31: 0.053070753 | AG31: 0.057899654 | AH31: 0.057945227 | AI31: 0.053251071 | AJ31: 0.047988045 | AK31: 0.047196665 | AL31: 0.045308878 | AM31: 0.042092236 | AN31: 0.041053946 | AO31: 0.04386576 | AP31: 0.042217536 | AQ31: 0.038623858 | AR31: 0.039010481
B32: Platform DAU | C32: You May Also Like | D32: % | F32: =J32 -> 0.10627931 | G32: =K32 -> 0.11167639 | H32: =IFERROR(F32/G32-1,"-") -> -0.0483279 | J32: 0.10627931 | K32: 0.11167639 | L32: 0.10891373 | M32: 0.1101136 | N32: 0.11005968 | O32: 0.11235439 | P32: 0.11773599 | Q32: 0.12095071 | R32: 0.12038984 | S32: 0.12242064 | T32: 0.12676393 | U32: 0.12565586 | V32: 0.12653313 | W32: 0.1340065 | X32: 0.13369049 | Y32: 0.13551387 | Z32: 0.13065522 | AA32: 0.13292103 | AB32: 0.13777819 | AC32: 0.1445591 | AD32: 0.14656102 | AE32: 0.1548483 | AF32: 0.16231076 | AG32: 0.1599296 | AH32: 0.15875417 | AI32: 0.15581737 | AJ32: 0.15640555 | AK32: 0.15667586 | AL32: 0.16143074 | AM32: 0.16488905 | AN32: 0.15985298 | AO32: 0.16276401 | AP32: 0.16106326 | AQ32: 0.15867595 | AR32: 0.16462781
B33: Platform DAU | C33: Post Purchase | D33: % | F33: =J33 -> 0.048411228 | G33: =K33 -> 0.048177693 | H33: =IFERROR(F33/G33-1,"-") -> 0.0048473692 | J33: 0.048411228 | K33: 0.048177693 | L33: 0.048429279 | M33: 0.044139529 | N33: 0.044627642 | O33: 0.048765606 | P33: 0.04655019 | Q33: 0.045876204 | R33: 0.046144347 | S33: 0.04580035 | T33: 0.044403873 | U33: 0.044712168 | V33: 0.044608946 | W33: 0.043433879 | X33: 0.044010069 | Y33: 0.042726022 | Z33: 0.043168052 | AA33: 0.044646247 | AB33: 0.044783238 | AC33: 0.042114006 | AD33: 0.040491322 | AE33: 0.044430934 | AF33: 0.042228431 | AG33: 0.040675702 | AH33: 0.043310996 | AI33: 0.042257723 | AJ33: 0.040977272 | AK33: 0.044525016 | AL33: 0.044464508 | AM33: 0.043618223 | AN33: 0.04384341 | AO33: 0.041085109 | AP33: 0.039296295 | AQ33: 0.039740052 | AR33: 0.040387832
B34: Platform DAU | C34: Private Domain | D34: % | F34: =J34 -> 0.099714453 | G34: =K34 -> 0.10144817 | H34: =IFERROR(F34/G34-1,"-") -> -0.017089682 | J34: 0.099714453 | K34: 0.10144817 | L34: 0.10525746 | M34: 0.11041439 | N34: 0.11457103 | O34: 0.11680969 | P34: 0.11825076 | Q34: 0.11989967 | R34: 0.12069839 | S34: 0.12202822 | T34: 0.12093453 | U34: 0.12335792 | V34: 0.12309065 | W34: 0.1243569 | X34: 0.12342562 | Y34: 0.12533318 | Z34: 0.12983857 | AA34: 0.13309463 | AB34: 0.13501488 | AC34: 0.13110093 | AD34: 0.13127086 | AE34: 0.13725635 | AF34: 0.14453007 | AG34: 0.14288286 | AH34: 0.14532765 | AI34: 0.14504468 | AJ34: 0.13944019 | AK34: 0.14270723 | AL34: 0.15086523 | AM34: 0.16127159 | AN34: 0.16676764 | AO34: 0.16539415 | AP34: 0.16529081 | AQ34: 0.16830034 | AR34: 0.17001211
B35: Platform DAU | C35: Live Streaming | D35: % | F35: =J35 -> 0.044743386 | G35: =K35 -> 0.04234045 | H35: =IFERROR(F35/G35-1,"-") -> 0.056752737 | J35: 0.044743386 | K35: 0.04234045 | L35: 0.040711972 | M35: 0.037848821 | N35: 0.037206177 | O35: 0.038064717 | P35: 0.038789788 | Q35: 0.037748417 | R35: 0.046196353 | S35: 0.045859781 | T35: 0.047289141 | U35: 0.053834268 | V35: 0.053520138 | W35: 0.052259371 | X35: 0.05510646 | Y35: 0.055488204 | Z35: 0.05563287 | AA35: 0.056085434 | AB35: 0.052807853 | AC35: 0.0468041 | AD35: 0.058286838 | AE35: 0.057441827 | AF35: 0.053074839 | AG35: 0.064151838 | AH35: 0.067580336 | AI35: 0.072896869 | AJ35: 0.071632445 | AK35: 0.073768796 | AL35: 0.048340919 | AM35: 0.010198689 | AN35: 0.010247783 | AO35: 0.010178 | AP35: 0.011174396 | AQ35: 0.0094832524 | AR35: 0.0080847181
B36: Platform DAU | C36: Video | D36: % | F36: =J36 -> 0.08232886 | G36: =K36 -> 0.074814573 | H36: =IFERROR(F36/G36-1,"-") -> 0.10043881 | J36: 0.08232886 | K36: 0.074814573 | L36: 0.066456137 | M36: 0.083672697 | N36: 0.073146698 | O36: 0.07010662 | P36: 0.060738908 | Q36: 0.053222418 | R36: 0.054371854 | S36: 0.043825271 | T36: 0.041924736 | U36: 0.044308784 | V36: 0.039484914 | W36: 0.039477868 | X36: 0.039695945 | Y36: 0.038794866 | Z36: 0.040262544 | AA36: 0.043439192 | AB36: 0.042037538 | AC36: 0.045218914 | AD36: 0.050540155 | AE36: 0.021299504 | AF36: 0.01694907 | AG36: 0.021082047 | AH36: 0.010217 | AI36: 0.0060554534 | AJ36: 0.0047932121 | AK36: 0.0039504254 | AL36: 0.004055535 | AM36: 0.0037903355 | AN36: 0.0032789451 | AO36: 0.0037561917 | AP36: 0.0025071023 | AQ36: 0.0016981068 | AR36: 0.0013459846
B37: Platform DAU | C37: Others | D37: % | F37: =J37 -> 0.11972739 | G37: =K37 -> 0.12349319 | H37: =IFERROR(F37/G37-1,"-") -> -0.030493941 | J37: 0.11972739 | K37: 0.12349319 | L37: 0.13608999 | M37: 0.11568316 | N37: 0.12352488 | O37: 0.13286399 | P37: 0.13311018 | Q37: 0.13701641 | R37: 0.13632141 | S37: 0.15304961 | T37: 0.15433458 | U37: 0.15101009 | V37: 0.16078716 | W37: 0.15963128 | X37: 0.16025748 | Y37: 0.16533731 | Z37: 0.16148531 | AA37: 0.15664848 | AB37: 0.1565157 | AC37: 0.15449329 | AD37: 0.15603332 | AE37: 0.17229448 | AF37: 0.17490302 | AG37: 0.17375506 | AH37: 0.18391672 | AI37: 0.18520049 | AJ37: 0.19545221 | AK37: 0.19386207 | AL37: 0.19934931 | AM37: 0.21379815 | AN37: 0.21472276 | AO37: 0.22014655 | AP37: 0.23028531 | AQ37: 0.23474789 | AR37: 0.23791557
C39: Rev% by Channel (incl. ads & non-item cards) | D39: UNIT
C40: Total | D40: % | F40: =J40 -> 1 | G40: =K40 -> 1 | H40: =IFERROR(F40/G40-1,"-") -> 0 | J40: 1 | K40: 1 | L40: 1 | M40: 1 | N40: 1 | O40: 1 | P40: 1 | Q40: 1 | R40: 1 | S40: 1 | T40: 1 | U40: 1 | V40: 1 | W40: 1 | X40: 1 | Y40: 1 | Z40: 1 | AA40: 1 | AB40: 1 | AC40: 1 | AD40: 1 | AE40: 1 | AF40: 1 | AG40: 1 | AH40: 1 | AI40: 1 | AJ40: 1 | AK40: 1 | AL40: 1 | AM40: 1 | AN40: 1 | AO40: 1 | AP40: 1 | AQ40: 1 | AR40: 1
B41: Platform DAU | C41: Search | D41: % | F41: =J41 -> 0.53274575 | G41: =K41 -> 0.55381101 | H41: =IFERROR(F41/G41-1,"-") -> -0.038036909 | J41: 0.53274575 | K41: 0.55381101 | L41: 0.55391964 | M41: 0.57611586 | N41: 0.58339775 | O41: 0.59375245 | P41: 0.60150991 | Q41: 0.59991286 | R41: 0.57513656 | S41: 0.58733916 | T41: 0.57156561 | U41: 0.57320879 | V41: 0.5738129 | W41: 0.59266767 | X41: 0.60201916 | Y41: 0.59365707 | Z41: 0.5943094 | AA41: 0.60144109 | AB41: 0.60583156 | AC41: 0.6095126 | AD41: 0.62852951 | AE41: 0.63123648 | AF41: 0.62676982 | AG41: 0.61501994 | AH41: 0.61192669 | AI41: 0.61866292 | AJ41: 0.61359655 | AK41: 0.62160499 | AL41: 0.63147799 | AM41: 0.63939209 | AN41: 0.65566624 | AO41: 0.64884041 | AP41: 0.65003552 | AQ41: 0.64537012 | AR41: 0.6461239
B42: Platform DAU | C42: Daily Discover | D42: % | F42: =J42 -> 0.15477315 | G42: =K42 -> 0.14564166 | H42: =IFERROR(F42/G42-1,"-") -> 0.062698338 | J42: 0.15477315 | K42: 0.14564166 | L42: 0.13935307 | M42: 0.13711035 | N42: 0.13569677 | O42: 0.12480676 | P42: 0.11209485 | Q42: 0.11038294 | R42: 0.11893421 | S42: 0.10848082 | T42: 0.11204265 | U42: 0.10045778 | V42: 0.093940329 | W42: 0.088059578 | X42: 0.092813047 | Y42: 0.096560636 | Z42: 0.1028063 | AA42: 0.097925449 | AB42: 0.097795685 | AC42: 0.090582533 | AD42: 0.084463018 | AE42: 0.084999022 | AF42: 0.085068591 | AG42: 0.09328984 | AH42: 0.09847547 | AI42: 0.097070283 | AJ42: 0.093625755 | AK42: 0.09475685 | AL42: 0.092946356 | AM42: 0.094546763 | AN42: 0.092983305 | AO42: 0.098106926 | AP42: 0.10228833 | AQ42: 0.10056387 | AR42: 0.10316692
B43: Platform DAU | C43: RCMD | D43: % | F43: =J43 -> 0.18115261 | G43: =K43 -> 0.17624974 | H43: =IFERROR(F43/G43-1,"-") -> 0.027817742 | J43: 0.18115261 | K43: 0.17624974 | L43: 0.18197216 | M43: 0.18479529 | N43: 0.18136266 | O43: 0.17886182 | P43: 0.18311178 | Q43: 0.17649548 | R43: 0.18483185 | S43: 0.17976172 | T43: 0.19044991 | U43: 0.20185786 | V43: 0.20086576 | W43: 0.18981005 | X43: 0.18303824 | Y43: 0.18897506 | Z43: 0.1861827 | AA43: 0.18616178 | AB43: 0.18362135 | AC43: 0.18987032 | AD43: 0.18211354 | AE43: 0.17822674 | AF43: 0.18516828 | AG43: 0.19006289 | AH43: 0.19215614 | AI43: 0.18538259 | AJ43: 0.19120827 | AK43: 0.18821625 | AL43: 0.19594266 | AM43: 0.18990625 | AN43: 0.18599443 | AO43: 0.19051995 | AP43: 0.19022822 | AQ43: 0.19866319 | AR43: 0.20270475
B44: Platform DAU | C44: Game | D44: % | F44: =J44 -> 0.037352924 | G44: =K44 -> 0.030900284 | H44: =IFERROR(F44/G44-1,"-") -> 0.2088214 | J44: 0.037352924 | K44: 0.030900284 | L44: 0.034133386 | M44: 0.01592766 | N44: 0.014531324 | O44: 0.018875695 | P44: 0.02215036 | Q44: 0.029240477 | R44: 0.032300141 | S44: 0.036630231 | T44: 0.040089747 | U44: 0.038007479 | V44: 0.044005395 | W44: 0.045780044 | X44: 0.044929871 | Y44: 0.050044121 | Z44: 0.051773476 | AA44: 0.052104856 | AB44: 0.052503079 | AC44: 0.051120101 | AD44: 0.048802081 | AE44: 0.053687651 | AF44: 0.053197333 | AG44: 0.050008285 | AH44: 0.045991941 | AI44: 0.049521928 | AJ44: 0.052327151 | AK44: 0.048569492 | AL44: 0.036187761 | AM44: 0.03580254 | AN44: 0.02603224 | AO44: 0.024867653 | AP44: 0.021644781 | AQ44: 0.020490141 | AR44: 0.014959707
B45: Platform DAU | C45: Brand | D45: % | F45: =J45 -> 0.050525695 | G45: =K45 -> 0.052403597 | H45: =IFERROR(F45/G45-1,"-") -> -0.035835368 | J45: 0.050525695 | K45: 0.052403597 | L45: 0.053902562 | M45: 0.055105066 | N45: 0.054121341 | O45: 0.055637643 | P45: 0.057670737 | Q45: 0.059944853 | R45: 0.06158105 | S45: 0.060624917 | T45: 0.059349654 | U45: 0.06002461 | V45: 0.062468524 | W45: 0.061281832 | X45: 0.060398702 | Y45: 0.056480694 | Z45: 0.053321259 | AA45: 0.052326204 | AB45: 0.051837637 | AC45: 0.052013338 | AD45: 0.049899457 | AE45: 0.050043163 | AF45: 0.048865972 | AG45: 0.051362374 | AH45: 0.050031163 | AI45: 0.049361001 | AJ45: 0.049241934 | AK45: 0.046852412 | AL45: 0.043445239 | AM45: 0.040352356 | AN45: 0.039323793 | AO45: 0.03766506 | AP45: 0.035803149 | AQ45: 0.034912675 | AR45: 0.033044724
B46: Platform DAU | C46: Live Streaming | D46: % | F46: =J46 -> 0.016187876 | G46: =K46 -> 0.017616144 | H46: =IFERROR(F46/G46-1,"-") -> -0.08107719 | J46: 0.016187876 | K46: 0.017616144 | L46: 0.017218844 | M46: 0.016915585 | N46: 0.01685605 | O46: 0.016384936 | P46: 0.016066477 | Q46: 0.017646675 | R46: 0.020585321 | S46: 0.020159969 | T46: 0.019510868 | U46: 0.018511182 | V46: 0.016824041 | W46: 0.015919948 | X46: 0.014765737 | Y46: 0.013331425 | Z46: 0.011136131 | AA46: 0.0098834228 | AB46: 0.0083804271 | AC46: 0.0068992915 | AD46: 0.0054220175 | AE46: 0.0017352004 | AF46: 0.00096674973 | AG46: 0.00062955958 | AH46: 0 | AI46: 0 | AJ46: 0 | AK46: 0 | AL46: 0 | AM46: 0 | AN46: 0 | AO46: 0 | AP46: 0 | AQ46: 0 | AR46: 0
...

Sheet ID
C1: Region:ID
H2: Updated Date | J2: 46000
C3: S&R&A Monthly Metrics | F3: =J3 -> 45992 | G3: =K3 -> 45962 | H3: MoM % | J3: 45992 | K3: 45962 | L3: 45931 | M3: 45901 | N3: 45870 | O3: 45839 | P3: 45809 | Q3: 45778 | R3: 45748 | S3: 45717 | T3: 45689 | U3: 45658 | V3: 45627 | W3: 45597 | X3: 45566 | Y3: 45536 | Z3: 45505 | AA3: 45474 | AB3: 45444 | AC3: 45413 | AD3: 45383 | AE3: 45352 | AF3: 45323 | AG3: 45292 | AH3: 45261 | AI3: 45231 | AJ3: 45200 | AK3: 45170 | AL3: 45139 | AM3: 45108 | AN3: 45078 | AO3: 45047 | AP3: 45017 | AQ3: 44986 | AR3: 44958 | AS3: 44927 | AT3: 44896 | AU3: 44866 | AV3: 44835 | AW3: 44805 | AX3: 44774 | AY3: 44743 | AZ3: 44713 | BA3: 44682 | BB3: 44652 | BC3: 44621 | BD3: 44593 | BE3: 44562
D5: UNIT
B6: Platform DAU | C6: Platform DAU | D6: # | F6: =J6 -> 54618939 | G6: =K6 -> 54210408 | H6: =IFERROR(F6/G6-1,"-") -> 0.0075360303 | J6: 54618939 | K6: 54210408 | L6: 52156874 | M6: 50991051 | N6: 49075213 | O6: 49635102 | P6: 47962513 | Q6: 47682472 | R6: 46785858 | S6: 50298117 | T6: 47039078 | U6: 45940812 | V6: 47791439 | W6: 46312987 | X6: 44969809 | Y6: 44483318 | Z6: 44001810 | AA6: 43099563 | AB6: 42159112 | AC6: 41831805 | AD6: 41791175 | AE6: 44333862 | AF6: 40731440 | AG6: 40148361 | AH6: 40862316 | AI6: 40996369 | AJ6: 39489412 | AK6: 36489810 | AL6: 34717402 | AM6: 33316420 | AN6: 31505956 | AO6: 31274689 | AP6: 32631046 | AQ6: 31086946 | AR6: 29064167 | AS6: 28853649 | AT6: 29821327 | AU6: 30314124 | AV6: 30334318 | AW6: 31204807 | AX6: 30285049 | AY6: 30024864 | AZ6: 29995464 | BA6: 29077319 | BB6: 31244244 | BC6: 28101253 | BD6: 27155831 | BE6: 26550724
B8: Avg No. of Modules in HP Layout | C8: Buyer | D8: # | F8: =J8 -> 9299773.4 | G8: =K8 -> 9167240.9 | H8: =IFERROR(F8/G8-1,"-") -> 0.014457194 | J8: 9299773.4 | K8: 9167240.9 | L8: 8617724 | M8: 8211149.3 | N8: 7936886.5 | O8: 8431891.3 | P8: 7881957.2 | Q8: 7619089.9 | R8: 7348113.4 | S8: 8526228.6 | T8: 7329374.3 | U8: 6624036.1 | V8: 7080341.7 | W8: 6896363.1 | X8: 6661934.5 | Y8: 6474075.2 | Z8: 6384100.3 | AA8: 6267046 | AB8: 5842865.4 | AC8: 5605666.6 | AD8: 5548449.2 | AE8: 7142240.8 | AF8: 5488059.7 | AG8: 5111628 | AH8: 5382372.3 | AI8: 5417933.9 | AJ8: 5691790.6 | AK8: 5382215 | AL8: 5305792.5 | AM8: 4949592.8 | AN8: 4172989.7 | AO8: 4003641.2 | AP8: 4423285 | AQ8: 4170947.5 | AR8: 3509372.4 | AS8: 3374318.6 | AT8: 3440722.6 | AU8: 3477646.6 | AV8: 3572391.8 | AW8: 3910777.5 | AX8: 4028777.5 | AY8: 4135524.3 | AZ8: 4039152.2 | BA8: 3735740.2 | BB8: 4730740.3 | BC8: 3739082.5 | BD8: 3417895.6 | BE8: 3195191.8
B9: Avg No. of Modules in HP Layout | C9: Buyer% | D9: % | F9: =J9 -> 0.17026646 | G9: =K9 -> 0.16910481 | H9: =IFERROR(F9/G9-1,"-") -> 0.0068693955 | J9: 0.17026646 | K9: 0.16910481 | L9: 0.16522701 | M9: 0.16103118 | N9: 0.16172903 | O9: 0.16987759 | P9: 0.16433579 | Q9: 0.15978806 | R9: 0.15705843 | S9: 0.16951388 | T9: 0.15581458 | U9: 0.14418631 | V9: 0.14815084 | W9: 0.14890776 | X9: 0.14814238 | Y9: 0.1455394 | Z9: 0.14508722 | AA9: 0.14540857 | AB9: 0.13859081 | AC9: 0.13400489 | AD9: 0.13276605 | AE9: 0.16110125 | AF9: 0.13473768 | AG9: 0.12731847 | AH9: 0.13171971 | AI9: 0.13215643 | AJ9: 0.1441346 | AK9: 0.14749913 | AL9: 0.15282804 | AM9: 0.14856317 | AN9: 0.13245082 | AO9: 0.12801538 | AP9: 0.1355545 | AQ9: 0.13417038 | AR9: 0.12074567 | AS9: 0.11694599 | AT9: 0.11537792 | AU9: 0.11472034 | AV9: 0.11776733 | AW9: 0.12532612 | AX9: 0.13302859 | AY9: 0.13773665 | AZ9: 0.13465877 | BA9: 0.12847609 | BB9: 0.15141158 | BC9: 0.1330575 | BD9: 0.12586231 | BE9: 0.12034293
B10: Avg No. of Modules in HP Layout | C10: Order | D10: # | F10: =J10 -> 15672498 | G10: =K10 -> 15775174 | H10: =IFERROR(F10/G10-1,"-") -> -0.0065087521 | J10: 15672498 | K10: 15775174 | L10: 14732062 | M10: 13920792 | N10: 13472649 | O10: 14402825 | P10: 13492389 | Q10: 12656810 | R10: 12090977 | S10: 14954659 | T10: 12172754 | U10: 10700178 | V10: 11893288 | W10: 11349069 | X10: 10832472 | Y10: 10532641 | Z10: 10421175 | AA10: 10128015 | AB10: 9422000.6 | AC10: 9005296.8 | AD10: 8914666.3 | AE10: 12135990 | AF10: 8741179.6 | AG10: 8004398.7 | AH10: 8736320.1 | AI10: 8696138.4 | AJ10: 9177421.6 | AK10: 8581383.5 | AL10: 8303691 | AM10: 7901592.9 | AN10: 6829151.8 | AO10: 6359977.1 | AP10: 7477420.9 | AQ10: 6891484.8 | AR10: 5648787.7 | AS10: 5317797.3 | AT10: 5593778 | AU10: 5481225.9 | AV10: 5647150.5 | AW10: 6255116.1 | AX10: 6728266.3 | AY10: 7062519 | AZ10: 6851324.1 | BA10: 6154880.5 | BB10: 8594126.4 | BC10: 6538882.5 | BD10: 5785703.7 | BE10: 5313141.8
C11: Order/U | D11: # | F11: =J11 -> 0.28694255 | G11: =K11 -> 0.290999 | H11: =IFERROR(F11/G11-1,"-") -> -0.013939732 | J11: 0.28694255 | K11: 0.290999 | L11: 0.28245677 | M11: 0.2730046 | N11: 0.27453063 | O11: 0.29017419 | P11: 0.28131114 | Q11: 0.26543947 | R11: 0.25843231 | S11: 0.29732047 | T11: 0.2587796 | U11: 0.23291226 | V11: 0.24885813 | W11: 0.24505155 | X11: 0.24088322 | Y11: 0.23677733 | Z11: 0.23683514 | AA11: 0.23499113 | AB11: 0.22348669 | AC11: 0.21527393 | AD11: 0.21331456 | AE11: 0.27374088 | AF11: 0.21460522 | AG11: 0.1993705 | AH11: 0.21379894 | AI11: 0.21211972 | AJ11: 0.23240208 | AK11: 0.23517205 | AL11: 0.23917951 | AM11: 0.23716813 | AN11: 0.21675749 | AO11: 0.2033586 | AP11: 0.22915051 | AQ11: 0.2216842 | AR11: 0.19435574 | AS11: 0.18430242 | AT11: 0.18757643 | AU11: 0.18081426 | AV11: 0.18616375 | AW11: 0.2004536 | AX11: 0.22216461 | AY11: 0.23522235 | AZ11: 0.22841201 | BA11: 0.2116729 | BB11: 0.27506271 | BC11: 0.23269007 | BD11: 0.21305566 | BE11: 0.20011288
B12: HP UV | C12: GMV | D12: # | F12: =J12 -> 1.0804285e+08 | G12: =K12 -> 107362748 | H12: =IFERROR(F12/G12-1,"-") -> 0.0063345999 | J12: 1.0804285e+08 | K12: 1.0736275e+08 | L12: 1.0139538e+08 | M12: 95827834 | N12: 92734227 | O12: 96341900 | P12: 90841525 | Q12: 86810844 | R12: 84546280 | S12: 1.0337518e+08 | T12: 93543933 | U12: 88136670 | V12: 91417977 | W12: 86185188 | X12: 84740176 | Y12: 81574988 | Z12: 77021527 | AA12: 76309258 | AB12: 72728239 | AC12: 73964759 | AD12: 71494501 | AE12: 91668745 | AF12: 72482351 | AG12: 70041008 | AH12: 75860064 | AI12: 74338202 | AJ12: 72956446 | AK12: 64643250 | AL12: 63280938 | AM12: 61772586 | AN12: 58168821 | AO12: 58728961 | AP12: 62753627 | AQ12: 59310014 | AR12: 52678003 | AS12: 48711122 | AT12: 51730954 | AU12: 51170531 | AV12: 52319865 | AW12: 58353265 | AX12: 58977554 | AY12: 60062590 | AZ12: 56752694 | BA12: 50166169 | BB12: 69907530 | BC12: 54267508 | BD12: 49459567 | BE12: 48553139
B14: Avg No. of Modules in HP Layout | C14: Ads Gross Rev | D14: # | F14: =J14 -> 4021522 | G14: =K14 -> 3956203.7 | H14: =IFERROR(F14/G14-1,"-") -> 0.016510343 | J14: 4021522 | K14: 3956203.7 | L14: 3508499.7 | M14: 3311650.6 | N14: 3074948.9 | O14: 3076334.4 | P14: 2870880.4 | Q14: 2514048.9 | R14: 2285438 | S14: 2796795.3 | T14: 2421795.8 | U14: 2273250.9 | V14: 2458682.6 | W14: 2245772.7 | X14: 2139772.1 | Y14: 1971253.8 | Z14: 1734083.5 | AA14: 1647179.5 | AB14: 1559243.8 | AC14: 1459845.4 | AD14: 1354327.3 | AE14: 1689229.5 | AF14: 1355750.4 | AG14: 1322916 | AH14: 1398208.1 | AI14: 1233219.2 | AJ14: 1190141.2 | AK14: 1078075.6 | AL14: 1013919.4 | AM14: 997804.78 | AN14: 939375.4 | AO14: 897325.22 | AP14: 952656.5 | AQ14: 954777.92 | AR14: 845753.33 | AS14: 784579.24
C15: Gross Take Rate | D15: % | F15: =J15 -> 0.037221547 | G15: =K15 -> 0.036848942 | H15: =IFERROR(F15/G15-1,"-") -> 0.010111689 | J15: 0.037221547 | K15: 0.036848942 | L15: 0.034602164 | M15: 0.034558337 | N15: 0.033158727 | O15: 0.031931427 | P15: 0.031603172 | Q15: 0.028960079 | R15: 0.027031799 | S15: 0.027054803 | T15: 0.025889395 | U15: 0.025792339 | V15: 0.026894957 | W15: 0.026057526 | X15: 0.025250976 | Y15: 0.024164929 | Z15: 0.022514271 | AA15: 0.021585578 | AB15: 0.021439317 | AC15: 0.019737039 | AD15: 0.018943097 | AE15: 0.018427541 | AF15: 0.018704559 | AG15: 0.018887735 | AH15: 0.018431412 | AI15: 0.016589306 | AJ15: 0.016313036 | AK15: 0.016677311 | AL15: 0.016022509 | AM15: 0.016152874 | AN15: 0.016149122 | AO15: 0.015279093 | AP15: 0.015180899 | AQ15: 0.01609809 | AR15: 0.016055152 | AS15: 0.016106778
B16: Avg No. of Modules in HP Layout | C16: Ads Direct ROI | D16: # | F16: =J16 -> 8.2895327 | G16: =K16 -> 8.3874931 | H16: =IFERROR(F16/G16-1,"-") -> -0.011679345 | J16: 8.2895327 | K16: 8.3874931 | L16: 8.4799086 | M16: 8.2792872 | N16: 8.0099934 | O16: 8.171763 | P16: 8.4562637 | Q16: 8.1356944 | R16: 8.3701215 | S16: 8.2742349 | T16: 7.7792749 | U16: 7.7678387 | V16: 7.4320219 | W16: 7.2319998 | X16: 6.996491 | Y16: 7.071816 | Z16: 7.1421799 | AA16: 6.8093504 | AB16: 6.4141707 | AC16: 6.3957797 | AD16: 6.4790232 | AE16: 6.261017 | AF16: 5.955 | AG16: 5.8934268 | AH16: 5.9575984 | AI16: 6.2891878 | AJ16: 6.4407653 | AK16: 6.4238087 | AL16: 6.5417707 | AM16: 6.3809701 | AN16: 6.3039311 | AO16: 6.3439469 | AP16: 6.3908585 | AQ16: 6.010546 | AR16: 6.050251 | AS16: 5.8399197
B18: Avg No. of Modules in HP Layout | C18: Ads Net Rev | D18: # | F18: =J18 -> 3841066.9 | G18: =K18 -> 3775870.9 | H18: =IFERROR(F18/G18-1,"-") -> 0.017266486 | J18: 3841066.9 | K18: 3775870.9 | L18: 3337642 | M18: 3134254.2 | N18: 2956712.7 | O18: 2979402.2 | P18: 2781206.2 | Q18: 2441520.9 | R18: 2224095.9 | S18: 2688034.2 | T18: 2329339.7 | U18: 2195502 | V18: 2348003 | W18: 2132807.2 | X18: 2023718.7 | Y18: 1865575.9 | Z18: 1638760.5 | AA18: 1559213.3 | AB18: 1491583.4 | AC18: 1397257 | AD18: 1282471.5
C19: Net Take Rate | D19: % | F19: =J19 -> 0.035551329 | G19: =K19 -> 0.035169283 | H19: =IFERROR(F19/G19-1,"-") -> 0.010863073 | J19: 0.035551329 | K19: 0.035169283 | L19: 0.032917099 | M19: 0.032707138 | N19: 0.031883726 | O19: 0.0309253 | P19: 0.030616023 | Q19: 0.028124607 | R19: 0.026306254 | S19: 0.026002703 | T19: 0.024901024 | U19: 0.024910199 | V19: 0.025684259 | W19: 0.024746795 | X19: 0.023881455 | Y19: 0.022869459 | Z19: 0.021276656 | AA19: 0.020432819 | AB19: 0.020508999 | AC19: 0.018890847 | AD19: 0.017938044
B21: Avg No. of Modules in HP Layout | C21: Ads Net Rev (excl 1p/sip) | D21: # | F21: =J21 -> 3841066.9 | G21: =K21 -> 3775870.9 | H21: =IFERROR(F21/G21-1,"-") -> 0.017266486 | J21: 3841066.9 | K21: 3775870.9 | L21: 3337642 | M21: 3134254.2 | N21: 2956712.7 | O21: 2979402.2 | P21: 2781206.2 | Q21: 2441520.9 | R21: 2224095.9 | S21: 2688034.2 | T21: 2329339.7 | U21: 2195502 | V21: 2348017.3 | W21: 2132868.4 | X21: 2023834.5 | Y21: 1865751.4 | Z21: 1638823.1 | AA21: 1559330.8 | AB21: 1491616.6 | AC21: 1397267.5 | AD21: 1282474
C22: Net Take Rate (excl 1p/sip) | D22: % | F22: =J22 -> 0.035551329 | G22: =K22 -> 0.035169283 | H22: =IFERROR(F22/G22-1,"-") -> 0.010863073 | J22: 0.035551329 | K22: 0.035169283 | L22: 0.032917099 | M22: 0.032707138 | N22: 0.031883726 | O22: 0.0309253 | P22: 0.030616023 | Q22: 0.028124607 | R22: 0.026306254 | S22: 0.026002703 | T22: 0.024901024 | U22: 0.024910199 | V22: 0.025684415 | W22: 0.024747505 | X22: 0.023882822 | Y22: 0.022871611 | Z22: 0.021277469 | AA22: 0.020434359 | AB22: 0.020509456 | AC22: 0.018890989 | AD22: 0.017938079
B24: Avg No. of Modules in HP Layout | C24: Commission Fee | D24: USD | F24: =J24 -> 7906537.9 | G24: =K24 -> 8037847.4 | H24: =IFERROR(F24/G24-1,"-") -> -0.016336399 | J24: 7906537.9 | K24: 8037847.4 | L24: 7453210.9 | M24: 6936257.7 | N24: 6717889.1 | O24: 7020840.1 | P24: 6691928.3 | Q24: 6136841.6 | R24: 5838252.7 | S24: 7598556.2 | T24: 6078019.6 | U24: 5802082.8 | V24: 6116486.9 | W24: 5712392.1 | X24: 5615767.1 | Y24: 5398553.3 | Z24: 4241870.5 | AA24: 4116570.4 | AB24: 3897195.2 | AC24: 3914972.5 | AD24: 3796230.6 | AE24: 5063331.8 | AF24: 3826420 | AG24: 3683511.3 | AH24: 3814808.7 | AI24: 2900494.1 | AJ24: 2816336.3 | AK24: 2536967 | AL24: 2476240.7 | AM24: 2430734 | AN24: 2221500.4 | AO24: 2192983.1 | AP24: 2425406.6 | AQ24: 2276819.2 | AR24: 1968976.9 | AS24: 1810007.8 | AT24: 1242313.9 | AU24: 1217465.2 | AV24: 1231949 | AW24: 1363854.9 | AX24: 1391032.4 | AY24: 1418095.7 | AZ24: 1349382.6 | BA24: 1201313.9 | BB24: 1735896.6 | BC24: 1276425.4 | BD24: 956597.89 | BE24: 771929.31
B25: Avg No. of Modules in HP Layout | C25: Commission Rate | D25: % | F25: =J25 -> 0.073179651 | G25: =K25 -> 0.07486626 | H25: =IFERROR(F25/G25-1,"-") -> -0.022528292 | J25: 0.073179651 | K25: 0.07486626 | L25: 0.073506412 | M25: 0.072382494 | N25: 0.072442391 | O25: 0.072874213 | P25: 0.073665961 | Q25: 0.070692109 | R25: 0.069053928 | S25: 0.073504645 | T25: 0.064975027 | U25: 0.065830519 | V25: 0.066906829 | W25: 0.066280438 | X25: 0.06627042 | Y25: 0.066179026 | Z25: 0.05507383 | AA25: 0.053945884 | AB25: 0.053585722 | AC25: 0.052930241 | AD25: 0.053098219 | AE25: 0.055235094 | AF25: 0.052791059 | AG25: 0.052590781 | AH25: 0.050287444 | AI25: 0.039017545 | AJ25: 0.038602981 | AK25: 0.03924566 | AL25: 0.039130911 | AM25: 0.03934972 | AN25: 0.03819057 | AO25: 0.037340744 | AP25: 0.038649663 | AQ25: 0.038388445 | AR25: 0.037377593 | AS25: 0.037157999 | AT25: 0.024014904 | AU25: 0.023792312 | AV25: 0.023546486 | AW25: 0.023372383 | AX25: 0.023585794 | AY25: 0.023610299 | AZ25: 0.023776539 | BA25: 0.023946694 | BB25: 0.024831324 | BC25: 0.023520988 | BD25: 0.019341008 | BE25: 0.015898649
B26: Avg No. of Modules in HP Layout | C26: Total Rebate | D26: USD | F26: =J26 -> 20379290 | G26: =K26 -> 21756623 | H26: =IFERROR(F26/G26-1,"-") -> -0.063306385 | J26: 20379290 | K26: 21756623 | L26: 19970083 | M26: 18656948 | N26: 17142376 | O26: 18038563 | P26: 18319279 | Q26: 17113363 | R26: 15723829 | S26: 22043888 | T26: 16333558 | U26: 14810674 | V26: 18654568 | W26: 16438123 | X26: 15843171 | Y26: 14851637 | Z26: 13164629 | AA26: 11958655 | AB26: 11014624 | AC26: 9821793.7 | AD26: 9794538.7 | AE26: 14491608 | AF26: 9507152.5 | AG26: 8450781.3 | AH26: 9034985.8 | AI26: 9279267.2 | AJ26: 11231362 | AK26: 10751194 | AL26: 10380536 | AM26: 9911189.6 | AN26: 7307600.9 | AO26: 6040016 | AP26: 7116120.3 | AQ26: 6879327.4 | AR26: 4921875.7 | AS26: 4224702.3 | AT26: 4382660 | AU26: 4313715.5 | AV26: 4742665.2 | AW26: 5946654.7 | AX26: 6840516.9 | AY26: 7415459.6 | AZ26: 7260593.1 | BA26: 6177381.7 | BB26: 9008185.4 | BC26: 6688877.3 | BD26: 5294690.1 | BE26: 4695628.1
C27: rebate per order
C28: Order% by Channel (incl. ads & non-item cards) | D28: UNIT
C29: Total | F29: =J29 -> 1 | G29: =K29 -> 1 | H29: =IFERROR(F29/G29-1,"-") -> 0 | J29: 1 | K29: 1 | L29: 1 | M29: 1 | N29: 1 | O29: 1 | P29: 1 | Q29: 1 | R29: 1 | S29: 1 | T29: 1 | U29: 1 | V29: 1 | W29: 1 | X29: 1 | Y29: 1 | Z29: 1 | AA29: 1 | AB29: 1 | AC29: 1 | AD29: 1 | AE29: 1 | AF29: 1 | AG29: 1 | AH29: 1 | AI29: 1 | AJ29: 1 | AK29: 1 | AL29: 1 | AM29: 1 | AN29: 1 | AO29: 1 | AP29: 1 | AQ29: 1 | AR29: 1 | AS29: 1
B30: Platform DAU | C30: Global Search | D30: % | F30: =J30 -> 0.41996937 | G30: =K30 -> 0.42577726 | H30: =IFERROR(F30/G30-1,"-") -> -0.013640683 | J30: 0.41996937 | K30: 0.42577726 | L30: 0.42476349 | M30: 0.43119977 | N30: 0.42819857 | O30: 0.42919794 | P30: 0.41273547 | Q30: 0.42084669 | R30: 0.42770686 | S30: 0.39863917 | T30: 0.39685122 | U30: 0.39825407 | V30: 0.39290243 | W30: 0.39890802 | X30: 0.39308662 | Y30: 0.38962709 | Z30: 0.3833187 | AA30: 0.38871926 | AB30: 0.38802654 | AC30: 0.38739968 | AD30: 0.39714656 | AE30: 0.36611955 | AF30: 0.3694637 | AG30: 0.36397809 | AH30: 0.3415155 | AI30: 0.34131013 | AJ30: 0.35124782 | AK30: 0.34302629 | AL30: 0.32689978 | AM30: 0.34663098 | AN30: 0.37104047 | AO30: 0.37401754 | AP30: 0.36044824 | AQ30: 0.35608091 | AR30: 0.36115304 | AS30: 0.3542502
B31: Platform DAU | C31: Daily Discover | D31: % | F31: =J31 -> 0.091565077 | G31: =K31 -> 0.089893455 | H31: =IFERROR(F31/G31-1,"-") -> 0.0185956 | J31: 0.091565077 | K31: 0.089893455 | L31: 0.088008602 | M31: 0.084875905 | N31: 0.086578474 | O31: 0.084053062 | P31: 0.084625933 | Q31: 0.081672886 | R31: 0.079451735 | S31: 0.083696766 | T31: 0.074281718 | U31: 0.067080015 | V31: 0.071027329 | W31: 0.070126872 | X31: 0.067736158 | Y31: 0.062681815 | Z31: 0.057106191 | AA31: 0.055258064 | AB31: 0.052601621 | AC31: 0.053063358 | AD31: 0.055862389 | AE31: 0.05515994 | AF31: 0.04908313 | AG31: 0.048905003 | AH31: 0.057890976 | AI31: 0.048247967 | AJ31: 0.04345408 | AK31: 0.037371086 | AL31: 0.032313602 | AM31: 0.032561236 | AN31: 0.034389908 | AO31: 0.033816235 | AP31: 0.040350131 | AQ31: 0.036961477 | AR31: 0.031359859 | AS31: 0.029303408
B32: Platform DAU | C32: You May Also Like | D32: % | F32: =J32 -> 0.086516118 | G32: =K32 -> 0.08375144 | H32: =IFERROR(F32/G32-1,"-") -> 0.033010516 | J32: 0.086516118 | K32: 0.08375144 | L32: 0.085108831 | M32: 0.078970376 | N32: 0.082113274 | O32: 0.081490081 | P32: 0.081431072 | Q32: 0.086429884 | R32: 0.090520723 | S32: 0.096970715 | T32: 0.093182467 | U32: 0.094073233 | V32: 0.092286597 | W32: 0.09037764 | X32: 0.099237489 | Y32: 0.10163042 | Z32: 0.10650116 | AA32: 0.10031307 | AB32: 0.096690748 | AC32: 0.098039865 | AD32: 0.1077038 | AE32: 0.11465562 | AF32: 0.10894815 | AG32: 0.11492997 | AH32: 0.11175827 | AI32: 0.11616819 | AJ32: 0.11954532 | AK32: 0.11765413 | AL32: 0.11878166 | AM32: 0.12555438 | AN32: 0.1382889 | AO32: 0.13010096 | AP32: 0.14169858 | AQ32: 0.13172659 | AR32: 0.11953902 | AS32: 0.12539835
B33: Platform DAU | C33: Post Purchase | D33: % | F33: =J33 -> 0.043654893 | G33: =K33 -> 0.047154686 | H33: =IFERROR(F33/G33-1,"-") -> -0.07421941 | J33: 0.043654893 | K33: 0.047154686 | L33: 0.048093715 | M33: 0.046480526 | N33: 0.041749682 | O33: 0.041510177 | P33: 0.044608421 | Q33: 0.039348766 | R33: 0.040181578 | S33: 0.041744702 | T33: 0.038085094 | U33: 0.034479424 | V33: 0.036755015 | W33: 0.033630065 | X33: 0.03368 | Y33: 0.034223019 | Z33: 0.032700935 | AA33: 0.029886629 | AB33: 0.031301776 | AC33: 0.031177443 | AD33: 0.03183591 | AE33: 0.031605038 | AF33: 0.031662947 | AG33: 0.031332243 | AH33: 0.031092616 | AI33: 0.03188738 | AJ33: 0.033230613 | AK33: 0.032188499 | AL33: 0.033228831 | AM33: 0.032345864 | AN33: 0.034027706 | AO33: 0.034476769 | AP33: 0.033526708 | AQ33: 0.033343902 | AR33: 0.033055402 | AS33: 0.031783088
B34: Platform DAU | C34: Private Domain | D34: % | F34: =J34 -> 0.10411558 | G34: =K34 -> 0.10487352 | H34: =IFERROR(F34/G34-1,"-") -> -0.0072272142 | J34: 0.10411558 | K34: 0.10487352 | L34: 0.10906744 | M34: 0.11377684 | N34: 0.11837862 | O34: 0.12411885 | P34: 0.12636083 | Q34: 0.12878147 | R34: 0.13015957 | S34: 0.1300153 | T34: 0.13175698 | U34: 0.13368413 | V34: 0.13530054 | W34: 0.13541694 | X34: 0.13719851 | Y34: 0.13659164 | Z34: 0.13676968 | AA34: 0.14033304 | AB34: 0.14570118 | AC34: 0.15200423 | AD34: 0.14508671 | AE34: 0.14122861 | AF34: 0.15631465 | AG34: 0.16616687 | AH34: 0.16257717 | AI34: 0.16901969 | AJ34: 0.16382091 | AK34: 0.15541787 | AL34: 0.161019 | AM34: 0.17388792 | AN34: 0.19199219 | AO34: 0.19827674 | AP34: 0.18730343 | AQ34: 0.19012399 | AR34: 0.19834319 | AS34: 0.20082029
B35: Platform DAU | C35: Live Streaming | D35: % | F35: =J35 -> 0.08335366 | G35: =K35 -> 0.074312321 | H35: =IFERROR(F35/G35-1,"-") -> 0.12166676 | J35: 0.08335366 | K35: 0.074312321 | L35: 0.068007256 | M35: 0.065635662 | N35: 0.061277047 | O35: 0.058915746 | P35: 0.061479249 | Q35: 0.064247878 | R35: 0.06102099 | S35: 0.07195856 | T35: 0.081163686 | U35: 0.08550827 | V35: 0.093707982 | W35: 0.092787418 | X35: 0.088238697 | Y35: 0.094974958 | Z35: 0.093550844 | AA35: 0.09646019 | AB35: 0.098576671 | AC35: 0.09018127 | AD35: 0.072478569 | AE35: 0.086900234 | AF35: 0.089594938 | AG35: 0.082313293 | AH35: 0.094692414 | AI35: 0.10579404 | AJ35: 0.11182447 | AK35: 0.12569799 | AL35: 0.1447071 | AM35: 0.097306962 | AN35: 0.016643547 | AO35: 0.01730511 | AP35: 0.016057056 | AQ35: 0.019432478 | AR35: 0.017133682 | AS35: 0.014087443
B36: Platform DAU | C36: Video | D36: % | F36: =J36 -> 0.070149769 | G36: =K36 -> 0.069265421 | H36: =IFERROR(F36/G36-1,"-") -> 0.012767532 | J36: 0.070149769 | K36: 0.069265421 | L36: 0.066751262 | M36: 0.065123105 | N36: 0.11508838 | O36: 0.099592145 | P36: 0.10122117 | Q36: 0.089049226 | R36: 0.076269268 | S36: 0.077573474 | T36: 0.062914067 | U36: 0.056162274 | V36: 0.060274249 | W36: 0.058561693 | X36: 0.059479951 | Y36: 0.060604477 | Z36: 0.062559167 | AA36: 0.074229668 | AB36: 0.0852208 | AC36: 0.091186661 | AD36: 0.10229945 | AE36: 0.0992466 | AF36: 0.054134726 | AG36: 0.049822001 | AH36: 0.05901811 | AI36: 0.029131201 | AJ36: 0.015638277 | AK36: 0.012484972 | AL36: 0.010359441 | AM36: 0.010411311 | AN36: 0.0098235333 | AO36: 0.00846729 | AP36: 0.0085756794 | AQ36: 0.0060657624 | AR36: 0.004574172 | AS36: 0.0037025626
B37: Platform DAU | C37: Others | D37: % | F37: =J37 -> 0.10067553 | G37: =K37 -> 0.10497189 | H37: =IFERROR(F37/G37-1,"-") -> -0.040928665 | J37: 0.10067553 | K37: 0.10497189 | L37: 0.11019941 | M37: 0.11393781 | N37: 0.066615947 | O37: 0.081121998 | P37: 0.087537858 | Q37: 0.089623201 | R37: 0.094689275 | S37: 0.099401319 | T37: 0.12176477 | U37: 0.13075859 | V37: 0.11774586 | W37: 0.12019135 | X37: 0.12134258 | Y37: 0.11966657 | Z37: 0.12749332 | AA37: 0.11480008 | AB37: 0.10188066 | AC37: 0.096947495 | AD37: 0.087586606 | AE37: 0.10508441 | AF37: 0.14079776 | AG37: 0.14255254 | AH37: 0.14145494 | AI37: 0.1584414 | AJ37: 0.16123851 | AK37: 0.17615917 | AL37: 0.17269059 | AM37: 0.18130135 | AN37: 0.20379374 | AO37: 0.20353935 | AP37: 0.21204017 | AQ37: 0.22626489 | AR37: 0.23484163 | AS37: 0.24065466
C39: Rev% by Channel (incl. ads & non-item cards) | D39: UNIT
C40: Total | D40: % | F40: =J40 -> 1 | G40: =K40 -> 1 | H40: =IFERROR(F40/G40-1,"-") -> 0 | J40: 1 | K40: 1 | L40: 1 | M40: 1 | N40: 1 | O40: 1 | P40: 1 | Q40: 1 | R40: 1 | S40: 1 | T40: 1 | U40: 1 | V40: 1 | W40: 1 | X40: 1 | Y40: 1 | Z40: 1 | AA40: 1 | AB40: 1 | AC40: 1 | AD40: 1 | AE40: 1 | AF40: 1 | AG40: 1 | AH40: 1 | AI40: 1 | AJ40: 1 | AK40: 1 | AL40: 1 | AM40: 1 | AN40: 1 | AO40: 1 | AP40: 1 | AQ40: 1 | AR40: 1 | AS40: 1
B41: Platform DAU | C41: Search | D41: % | F41: =J41 -> 0.58969187 | G41: =K41 -> 0.57361004 | H41: =IFERROR(F41/G41-1,"-") -> 0.028036184 | J41: 0.58969187 | K41: 0.57361004 | L41: 0.58462806 | M41: 0.5868641 | N41: 0.60795106 | O41: 0.60203608 | P41: 0.60334048 | Q41: 0.61379186 | R41: 0.60662746 | S41: 0.56203858 | T41: 0.59046288 | U41: 0.59435176 | V41: 0.58177018 | W41: 0.59633442 | X41: 0.61503125 | Y41: 0.62950905 | Z41: 0.62335844 | AA41: 0.63759731 | AB41: 0.63832988 | AC41: 0.6382384 | AD41: 0.6349601 | AE41: 0.64101139 | AF41: 0.65202688 | AG41: 0.64812971 | AH41: 0.62860913 | AI41: 0.62773482 | AJ41: 0.62947363 | AK41: 0.62523932 | AL41: 0.63151651 | AM41: 0.63927808 | AN41: 0.64677894 | AO41: 0.66486895 | AP41: 0.65127046 | AQ41: 0.65701706 | AR41: 0.66104481 | AS41: 0.65819717
B42: Platform DAU | C42: Daily Discover | D42: % | F42: =J42 -> 0.1268152 | G42: =K42 -> 0.13161053 | H42: =IFERROR(F42/G42-1,"-") -> -0.036435794 | J42: 0.1268152 | K42: 0.13161053 | L42: 0.12555211 | M42: 0.1200046 | N42: 0.11965919 | O42: 0.13082606 | P42: 0.12731612 | Q42: 0.10818396 | R42: 0.10572316 | S42: 0.12577915 | T42: 0.10382088 | U42: 0.098257336 | V42: 0.099857088 | W42: 0.098562225 | X42: 0.092076751 | Y42: 0.095469868 | Z42: 0.090646429 | AA42: 0.086968263 | AB42: 0.091481557 | AC42: 0.099372058 | AD42: 0.094138943 | AE42: 0.086130234 | AF42: 0.078662376 | AG42: 0.078455972 | AH42: 0.09254248 | AI42: 0.095729066 | AJ42: 0.096207659 | AK42: 0.091957191 | AL42: 0.088454769 | AM42: 0.090442709 | AN42: 0.093660499 | AO42: 0.092215745 | AP42: 0.10186924 | AQ42: 0.1047963 | AR42: 0.10232166 | AS42: 0.10443903
B43: Platform DAU | C43: RCMD | D43: % | F43: =J43 -> 0.15325178 | G43: =K43 -> 0.16818099 | H43: =IFERROR(F43/G43-1,"-") -> -0.08876875 | J43: 0.15325178 | K43: 0.16818099 | L43: 0.16074698 | M43: 0.16997706 | N43: 0.16424869 | O43: 0.16307881 | P43: 0.16652002 | Q43: 0.16900749 | R43: 0.17519943 | S43: 0.19482316 | T43: 0.17859825 | U43: 0.17627346 | V43: 0.18626135 | W43: 0.1739375 | X43: 0.15819395 | Y43: 0.14970339 | Z43: 0.155265 | AA43: 0.1528094 | AB43: 0.15241404 | AC43: 0.1477982 | AD43: 0.15861098 | AE43: 0.16887171 | AF43: 0.16630154 | AG43: 0.16907168 | AH43: 0.17652545 | AI43: 0.17655698 | AJ43: 0.171796 | AK43: 0.17485574 | AL43: 0.17468502 | AM43: 0.18347027 | AN43: 0.1797064 | AO43: 0.16983415 | AP43: 0.17418958 | AQ43: 0.172274 | AR43: 0.17395098 | AS43: 0.18257204
B44: Platform DAU | C44: Game | D44: % | F44: =J44 -> 0.01376999 | G44: =K44 -> 0.017354993 | H44: =IFERROR(F44/G44-1,"-") -> -0.206569 | J44: 0.01376999 | K44: 0.017354993 | L44: 0.01950937 | M44: 0.022948522 | N44: 0.012778374 | O44: 0.008502996 | P44: 0.0073900625 | Q44: 0.013582368 | R44: 0.016504283 | S44: 0.017524668 | T44: 0.025038388 | U44: 0.032241551 | V44: 0.031034058 | W44: 0.032347495 | X44: 0.035964255 | Y44: 0.033670766 | Z44: 0.044839024 | AA44: 0.043521793 | AB44: 0.04394579 | AC44: 0.045923271 | AD44: 0.043444316 | AE44: 0.039918775 | AF44: 0.047847058 | AG44: 0.05121125 | AH44: 0.047483619 | AI44: 0.045612627 | AJ44: 0.047233958 | AK44: 0.054707764 | AL44: 0.055418102 | AM44: 0.039385677 | AN44: 0.036457993 | AO44: 0.029616026 | AP44: 0.030190668 | AQ44: 0.024964352 | AR44: 0.022151852 | AS44: 0.015825161
B45: Platform DAU | C45: Brand | D45: % | F45: =J45 -> 0.047643765 | G45: =K45 -> 0.045308373 | H45: =IFERROR(F45/G45-1,"-") -> 0.051544388 | J45: 0.047643765 | K45: 0.045308373 | L45: 0.049619268 | M45: 0.050312713 | N45: 0.050000167 | O45: 0.050122027 | P45: 0.051162735 | Q45: 0.053573104 | R45: 0.054793112 | S45: 0.054124383 | T45: 0.05288292 | U45: 0.050973333 | V45: 0.053246243 | W45: 0.056967011 | X45: 0.058209776 | Y45: 0.056161369 | Z45: 0.05240348 | AA45: 0.050681097 | AB45: 0.049931301 | AC45: 0.049756268 | AD45: 0.05317564 | AE45: 0.050095764 | AF45: 0.050900906 | AG45: 0.050678763 | AH45: 0.054030887 | AI45: 0.052146543 | AJ45: 0.055287697 | AK45: 0.053239939 | AL45: 0.0499256 | AM45: 0.047423263 | AN45: 0.043396167 | AO45: 0.043465128 | AP45: 0.042480058 | AQ45: 0.040948289 | AR45: 0.040530692 | AS45: 0.038966602
B46: Platform DAU | C46: Live Streaming | D46: % | F46: =J46 -> 0.024494158 | G46: =K46 -> 0.026870798 | H46: =IFERROR(F46/G46-1,"-") -> -0.088446943 | J46: 0.024494158 | K46: 0.026870798 | L46: 0.029504475 | M46: 0.026314053 | N46: 0.027137042 | O46: 0.028025882 | P46: 0.028483391 | Q46: 0.028987933 | R46: 0.029771284 | S46: 0.035262348 | T46: 0.038562365 | U46: 0.039307726 | V46: 0.038360765 | W46: 0.032752197 | X46: 0.031442241 | Y46: 0.031963428 | Z46: 0.03134506 | AA46: 0.027438104 | AB46: 0.023299004 | AC46: 0.018797505 | AD46: 0.015663153 | AE46: 0.01172272 | AF46: 0.0040240292 | AG46: 0.0024525627 | AH46: 0.0019188712 | AI46: 0 | AJ46: 0 | AK46: 0 | AL46: 0 | AM46: 0 | AN46: 0 | AO46: 0 | AP46: 0 | AQ46: 0 | AR46: 0 | AS46: 0
B47: Platform DAU | C47: Video | D47: % | F47: =J47 -> 0.014279724 | G47: =K47 -> 0.015527458 | H47: =IFERROR(F47/G47-1,"-") -> -0.080356565 | J47: 0.014279724 | K47: 0.015527458 | L47: 0.016695458 | M47: 0.015213484 | N47: 0.015222858 | O47: 0.015013956 | P47: 0.013222299 | Q47: 0.011503892 | R47: 0.0097562799 | S47: 0.0087045813 | T47: 0.0085484009 | U47: 0.0065791347 | V47: 0.0067997352 | W47: 0.0048633757 | X47: 0.0047617032 | Y47: 0.003270651 | Z47: 0.0021213629 | AA47: 0.0009839796 | AB47: 0.00026130162 | AC47: 4.4361952e-05 | AD47: 6.8741783e-06 | AE47: 0 | AF47: 0 | AG47: 0 | AH47: 0 | AI47: 0 | AJ47: 0 | AK47: 0 | AL47: 0 | AM47: 0 | AN47: 0 | AO47: 0 | AP47: 0 | AQ47: 0 | AR47: 0 | AS47: 0
...

Sheet PH
C1: Region:PH
H2: Updated Date | J2: =ID!J2 -> 46000
C3: S&R&A Monthly Metrics | F3: =J3 -> 45992 | G3: =K3 -> 45962 | H3: MoM % | J3: 45992 | K3: 45962 | L3: 45931 | M3: 45901 | N3: 45870 | O3: 45839 | P3: 45809 | Q3: 45778 | R3: 45748 | S3: 45717 | T3: 45689 | U3: 45658 | V3: 45627 | W3: 45597 | X3: 45566 | Y3: 45536 | Z3: 45505 | AA3: 45474 | AB3: 45444 | AC3: 45413 | AD3: 45383 | AE3: 45352 | AF3: 45323 | AG3: 45292 | AH3: 45261 | AI3: 45231 | AJ3: 45200 | AK3: 45170 | AL3: 45139 | AM3: 45108 | AN3: 45078 | AO3: 45047 | AP3: 45017 | AQ3: 44986 | AR3: 44958 | AS3: 44927 | AT3: 44896 | AU3: 44866 | AV3: 44835 | AW3: 44805 | AX3: 44774 | AY3: 44743 | AZ3: 44713 | BA3: 44682 | BB3: 44652 | BC3: 44621 | BD3: 44593 | BE3: 44562
D5: UNIT
B6: Platform DAU | C6: Platform DAU | D6: # | F6: =J6 -> 18339237 | G6: =K6 -> 17281144 | H6: =IFERROR(F6/G6-1,"-") -> 0.061228154 | J6: 18339237 | K6: 17281144 | L6: 17102700 | M6: 16937962 | N6: 17079585 | O6: 17136959 | P6: 17384993 | Q6: 16918354 | R6: 16096330 | S6: 16817606 | T6: 16879457 | U6: 16998222 | V6: 17538042 | W6: 16611990 | X6: 16105665 | Y6: 16046110 | Z6: 15844415 | AA6: 15872346 | AB6: 15339637 | AC6: 15083827 | AD6: 15403686 | AE6: 15497054 | AF6: 15283955 | AG6: 15486221 | AH6: 15975879 | AI6: 15318218 | AJ6: 13995607 | AK6: 13468806 | AL6: 13164196 | AM6: 12108635 | AN6: 11705488 | AO6: 11815337 | AP6: 11377308 | AQ6: 11598694 | AR6: 11452259 | AS6: 11929554 | AT6: 12147941 | AU6: 11775940 | AV6: 11305193 | AW6: 11720115 | AX6: 11754149 | AY6: 11414976 | AZ6: 11119466 | BA6: 10945058 | BB6: 10583459 | BC6: 10869979 | BD6: 10647242 | BE6: 10485570
B8: Avg No. of Modules in HP Layout | C8: Buyer | D8: # | F8: =J8 -> 3612321.1 | G8: =K8 -> 3026805.7 | H8: =IFERROR(F8/G8-1,"-") -> 0.19344336 | J8: 3612321.1 | K8: 3026805.7 | L8: 2806184.9 | M8: 2716879.2 | N8: 2750229.2 | O8: 2768812.5 | P8: 2882284.9 | Q8: 2727457.3 | R8: 2395353.1 | S8: 2567528.7 | T8: 2413389.8 | U8: 2590223.8 | V8: 2709780.2 | W8: 2458284.6 | X8: 2155046.2 | Y8: 2304647.8 | Z8: 2274543.5 | AA8: 2345434.1 | AB8: 2202877.2 | AC8: 2194342.7 | AD8: 2149906.1 | AE8: 2312581.5 | AF8: 2289297.7 | AG8: 2309156.1 | AH8: 2741853.7 | AI8: 2550264.9 | AJ8: 2184323.8 | AK8: 2163916.5 | AL8: 2130713.2 | AM8: 1890641.8 | AN8: 1696701.4 | AO8: 1645089 | AP8: 1502517.4 | AQ8: 1567194.1 | AR8: 1448790.4 | AS8: 1560080.7 | AT8: 1671519.1 | AU8: 1606311.3 | AV8: 1454289.2 | AW8: 1516528.5 | AX8: 1639966.1 | AY8: 1622938.1
B9: Avg No. of Modules in HP Layout | C9: Buyer% | D9: % | F9: =J9 -> 0.19697227 | G9: =K9 -> 0.17515076 | H9: =IFERROR(F9/G9-1,"-") -> 0.12458697 | J9: 0.19697227 | K9: 0.17515076 | L9: 0.16407847 | M9: 0.16040178 | N9: 0.16102436 | O9: 0.16156965 | P9: 0.16579154 | Q9: 0.16121292 | R9: 0.14881362 | S9: 0.1526691 | T9: 0.14297793 | U9: 0.15238205 | V9: 0.1545087 | W9: 0.14798255 | X9: 0.13380672 | Y9: 0.14362658 | Z9: 0.14355491 | AA9: 0.14776859 | AB9: 0.14360687 | AC9: 0.14547652 | AD9: 0.13957089 | AE9: 0.14922717 | AF9: 0.14978438 | AG9: 0.14911037 | AH9: 0.17162459 | AI9: 0.16648574 | AJ9: 0.1560721 | AK9: 0.16066135 | AL9: 0.16185669 | AM9: 0.15613996 | AN9: 0.14494922 | AO9: 0.13923335 | AP9: 0.13206264 | AQ9: 0.13511814 | AR9: 0.12650695 | AS9: 0.13077444 | AT9: 0.13759691 | AU9: 0.1364062 | AV9: 0.12863904 | AW9: 0.12939537 | AX9: 0.13952232 | AY9: 0.14217621
B10: Avg No. of Modules in HP Layout | C10: Order | D10: # | F10: =J10 -> 6293860.1 | G10: =K10 -> 5200335.3 | H10: =IFERROR(F10/G10-1,"-") -> 0.21027967 | J10: 6293860.1 | K10: 5200335.3 | L10: 4680338 | M10: 4477740.5 | N10: 4503779.5 | O10: 4500213.5 | P10: 4750308.4 | Q10: 4423100.9 | R10: 3752026.3 | S10: 4029361.1 | T10: 3705073.8 | U10: 4011587.4 | V10: 4369959.4 | W10: 3916184.8 | X10: 3251421.3 | Y10: 3494131.3 | Z10: 3398056.9 | AA10: 3544385.1 | AB10: 3322701.8 | AC10: 3303896.6 | AD10: 3188169.3 | AE10: 3417076.2 | AF10: 3351443.1 | AG10: 3417429.6 | AH10: 4225934.7 | AI10: 3867057 | AJ10: 3255884.6 | AK10: 3179289.2 | AL10: 3158281.6 | AM10: 2896906.7 | AN10: 2597983.4 | AO10: 2523219.5 | AP10: 2317777.5 | AQ10: 2429740.2 | AR10: 2198570 | AS10: 2356529.2 | AT10: 2635698.8 | AU10: 2518974.5 | AV10: 2238847.6 | AW10: 2334330.3 | AX10: 2595115.2 | AY10: 2600493.9
C11: Order/U | D11: # | F11: =J11 -> 0.34319095 | G11: =K11 -> 0.3009254 | H11: =IFERROR(F11/G11-1,"-") -> 0.14045191 | J11: 0.34319095 | K11: 0.3009254 | L11: 0.27366076 | M11: 0.26436124 | N11: 0.26369373 | O11: 0.26260281 | P11: 0.27324189 | Q11: 0.26143801 | R11: 0.23309825 | S11: 0.23959184 | T11: 0.21950196 | U11: 0.23600042 | V11: 0.24917031 | W11: 0.23574448 | X11: 0.20188059 | Y11: 0.21775567 | Z11: 0.21446402 | AA11: 0.22330569 | AB11: 0.2166089 | AC11: 0.2190357 | AD11: 0.20697444 | AE11: 0.22049844 | AF11: 0.21927853 | AG11: 0.22067551 | AH11: 0.26451971 | AI11: 0.25244822 | AJ11: 0.23263618 | AK11: 0.23604834 | AL11: 0.2399145 | AM11: 0.23924304 | AN11: 0.22194576 | AO11: 0.2135546 | AP11: 0.20371932 | AQ11: 0.20948394 | AR11: 0.19197697 | AS11: 0.19753707 | AT11: 0.21696672 | AU11: 0.21390857 | AV11: 0.19803709 | AW11: 0.19917299 | AX11: 0.22078291 | AY11: 0.22781422
B12: HP UV | C12: GMV | D12: # | F12: =J12 -> 42286510 | G12: =K12 -> 37650711 | H12: =IFERROR(F12/G12-1,"-") -> 0.12312647 | J12: 42286510 | K12: 37650711 | L12: 33650765 | M12: 32647154 | N12: 31520378 | O12: 31797980 | P12: 33467383 | Q12: 31750349 | R12: 27462655 | S12: 27895533 | T12: 26396915 | U12: 27575230 | V12: 31454793 | W12: 28474898 | X12: 25150762 | Y12: 25605192 | Z12: 24238245 | AA12: 24248512 | AB12: 23258026 | AC12: 23737761 | AD12: 23504662 | AE12: 23609902 | AF12: 23883776 | AG12: 24785441 | AH12: 29851590 | AI12: 25895153 | AJ12: 21966750 | AK12: 21635659 | AL12: 21872099 | AM12: 20367446 | AN12: 19125161 | AO12: 19002069 | AP12: 18792346 | AQ12: 19587979 | AR12: 19544386 | AS12: 20073499 | AT12: 22624098 | AU12: 21676959 | AV12: 18223157 | AW12: 20003831 | AX12: 21136306 | AY12: 20522158
